Workbook
Name NOM_ENT: '⚙️ Paramètres'!$C$6
Name ANNEE: '⚙️ Paramètres'!$C$8
Name SOLDE_INIT: '⚙️ Paramètres'!$C$9
Name REGIME_TVA: '⚙️ Paramètres'!$C$12
Name TVA_DEFAUT: '⚙️ Paramètres'!$C$13
Name CFE_ANNUELLE: '⚙️ Paramètres'!$C$14
Name STATUT: '⚙️ Paramètres'!$C$17
Name TAUX_CHG_AS: '⚙️ Paramètres'!$C$18
Name TAUX_CHG_TNS: '⚙️ Paramètres'!$C$19
Name SALAIRE_NET: '⚙️ Paramètres'!$C$20
Name TAUX_CHARGES: '⚙️ Paramètres'!$C$21
Name SEUIL_IS: '⚙️ Paramètres'!$F$6
Name TAUX_IS_REDUIT: '⚙️ Paramètres'!$F$7
Name TAUX_IS_NORMAL: '⚙️ Paramètres'!$F$8
Name JOUR_URSSAF: '⚙️ Paramètres'!$C$25
Name FLAT_TAX: '⚙️ Paramètres'!$C$26
Name TVA_AC_JUIL: '⚙️ Paramètres'!$C$27
Name TVA_AC_DEC: '⚙️ Paramètres'!$C$28
Name BAREME_KM: '⚙️ Paramètres'!$E$13:$I$17
Name LISTE_TVA: '⚙️ Paramètres'!$F$21:$F$25
Name LISTE_CATEGORIES: '📋 Budget'!$B$16:$B$30

Sheet 🏠 Dashboard
A1: ="🏠 "&UPPER(NOM_ENT)&" — TABLEAU DE BORD "&ANNEE
A2: En clair : toute votre entreprise en un coup d'œil — santé, alertes et chiffres clés.
B3: VUE D'ENSEMBLE | K3: ="🚀 Configuration : "&COUNTIF('🚀 Démarrer ici'!$I$7:$I$19,"✅")&"/5 étapes" | P3: Zone de calcul — ne pas supprimer
B4: CA RÉALISÉ (HT) | D4: DÉPENSES RÉALISÉES | F4: RÉSULTAT | H4: TRÉSORERIE ACTUELLE | J4: TVA ESTIMÉE À PAYER | L4: PROCHAINE ÉCHÉANCE | P4: Mois en cours (borné à l'année) | Q4: =IF(YEAR(TODAY())>ANNEE,12,IF(YEAR(TODAY())<ANNEE,1,MONTH(TODAY())))
B5: ='📊 Suivi mensuel'!$D$19 | D5: ='📊 Suivi mensuel'!$G$19 | F5: ='📊 Suivi mensuel'!$J$19 | H5: =INDEX('🏦 Trésorerie'!$C$20:$N$20,IF(YEAR(TODAY())>ANNEE,12,IF(YEAR(TODAY())<ANNEE,1,MONTH(TODAY())))) | J5: ='🧾 TVA & Impôts'!$H$13 | L5: =IF('📅 Échéancier'!$J$5=0,"—",'📅 Échéancier'!$J$5) | P5: CA réalisé cumulé à date | Q5: =SUM('📊 Suivi mensuel'!$D$7:INDEX('📊 Suivi mensuel'!$D$7:$D$18,$Q$4))
B6: chiffre d'affaires facturé | D6: HT + salaire & charges | F6: CA − dépenses | H6: solde fin du mois en cours | J6: estimation — mois en cours | L6: =IF('📅 Échéancier'!$J$5=0,"aucune échéance à venir",'📅 Échéancier'!$J$6&" · "&ROUND('📅 Échéancier'!$J$7,0)&" € · dans "&'📅 Échéancier'!$J$8&" j") | P6: Dépenses réalisées cumulées à date | Q6: =SUM('📊 Suivi mensuel'!$G$7:INDEX('📊 Suivi mensuel'!$G$7:$G$18,$Q$4))
P7: CA prévu cumulé à date | Q7: =SUM('📊 Suivi mensuel'!$C$7:INDEX('📊 Suivi mensuel'!$C$7:$C$18,$Q$4))
B8: ⏳ RUNWAY | E8: 📈 MARGE NETTE | H8: 🎯 SEUIL DE RENTABILITÉ | K8: 🔮 RÉSULTAT PROJETÉ | P8: Dépenses prévues cumulées à date | Q8: =SUM('📊 Suivi mensuel'!$F$7:INDEX('📊 Suivi mensuel'!$F$7:$F$18,$Q$4))
B9: =IF($Q$19=0,"—",ROUND($Q$11,1)&" mois d'autonomie") | E9: =IF($Q$19=0,"—",ROUND($Q$12*100,0)&" % du CA") | H9: =IF($Q$19=0,"—",ROUND($Q$17,0)&" €/mois de CA pour couvrir vos charges") | K9: =IF($Q$19=0,"—",ROUND($Q$18,0)&" € fin d'année (run-rate)") | P9: Trésorerie actuelle | Q9: =INDEX('🏦 Trésorerie'!$C$20:$N$20,$Q$4)
P10: Décaissements mensuels moyens | Q10: =IFERROR(SUM('🏦 Trésorerie'!$C$19:INDEX('🏦 Trésorerie'!$C$19:$N$19,$Q$4))/$Q$4,0)
B11: SANTÉ & RECOMMANDATIONS | P11: Runway (mois d'autonomie) | Q11: =IFERROR(IF($Q$10<=0,99,MAX(0,$Q$9)/$Q$10),0)
B12: 🩺 SANTÉ FINANCIÈRE | D12: =IF($Q$19=0,"— en attente de données",IF($Q$25>=75,"🟢 Solide",IF($Q$25>=40,"🟡 À surveiller","🔴 Fragile"))) | H12: 🧭 VOS RECOMMANDATIONS DU MOMENT | P12: Marge nette réalisée | Q12: =IFERROR(($Q$5-$Q$6)/$Q$5,0)
B13: =IF($Q$19=0,"—",$Q$25&" / 100") | D13: =IF($Q$19=0,"",REPT("█",ROUND($Q$25/5,0))&REPT("░",20-ROUND($Q$25/5,0))) | H13: =IF($Q$19=0,"— En attente de vos premières saisies.",IF($Q$11<3,"⚠️ Moins de 3 mois d'autonomie de trésorerie. Priorité : relancez vos factures non encaissées ("&ROUND($Q$16,0)&" € en attente) et décalez les dépenses non urgentes.","✓ RAS — trésorerie : "&ROUND($Q$11,1)&" mois d'autonomie devant vous.")) | P13: Dépenses réalisées / prévues à date | Q13: =IFERROR($Q$6/$Q$8,1)
B14: Trésorerie (30 %) | D14: =IF($Q$19=0,"—",$Q$20&"/100") | E14: =IF($Q$19=0,"— en attente de données","Autonomie : "&ROUND($Q$11,1)&" mois de décaissements devant vous (objectif : 6).") | H14: =IF($Q$19=0,"— En attente de vos premières saisies.",IF($Q$13>1.1,"📊 Vos dépenses dépassent le budget de "&ROUND(($Q$13-1)*100,0)&" %. Consultez le 📊 Suivi mensuel pour repérer la catégorie en cause.","✓ RAS — budget respecté à ce stade de l'année.")) | P14: CA réalisé / prévu à date | Q14: =IFERROR($Q$5/$Q$7,0)
B15: Rentabilité (25 %) | D15: =IF($Q$19=0,"—",$Q$21&"/100") | E15: =IF($Q$19=0,"— en attente de données","Marge nette : "&ROUND($Q$12*100,0)&" % du CA (objectif : 20 %).") | H15: =IF('📅 Échéancier'!$J$5=0,"✓ RAS — aucune échéance à venir.",IF(AND('📅 Échéancier'!$J$8<15,$Q$9<'📅 Échéancier'!$J$7),"📅 Échéance "&'📅 Échéancier'!$J$6&" dans "&'📅 Échéancier'!$J$8&" j : prévoyez "&ROUND('📅 Échéancier'!$J$7,0)&" € sur le compte.","✓ RAS — prochaine échéance sous contrôle.")) | P15: Provisions du mois (estimation) | Q15: ='🧾 TVA & Impôts'!$H$17
B16: Respect du budget (20 %) | D16: =IF($Q$19=0,"—",$Q$22&"/100") | E16: =IF($Q$19=0,"— en attente de données","Dépenses : "&ROUND($Q$13*100,0)&" % du budget prévu à date (objectif : 100 % maximum).") | H16: =IF($Q$19=0,"— En attente de vos premières saisies.",IF(AND($Q$26>0,$Q$16>0.2*$Q$26),"💶 "&ROUND($Q$16,0)&" € facturés mais non encaissés. Pensez aux relances — c'est de la trésorerie qui dort.","✓ RAS — encaissements à jour.")) | P16: Factures non encaissées (TTC) | Q16: =SUMIFS('💰 Recettes'!$H$10:$H$209,'💰 Recettes'!$I$10:$I$209,"Non")
B17: Dynamique CA (15 %) | D17: =IF($Q$19=0,"—",$Q$23&"/100") | E17: =IF($Q$19=0,"— en attente de données","CA réalisé : "&ROUND($Q$14*100,0)&" % du prévisionnel à date.") | H17: =IF($Q$19=0,"🌱 Commencez à saisir vos factures et vos dépenses : vos recommandations personnalisées s'afficheront ici.",IF(COUNTIF($H$13:$H$16,"✓*")=4,"🎉 Tous les voyants sont au vert ce mois-ci. Continuez comme ça !","☝️ Traitez les points ci-dessus — le reste est sous contrôle.")) | P17: Seuil de rentabilité mensuel | Q17: =IFERROR($Q$6/$Q$4,0)
B18: Provisions (10 %) | D18: =IF($Q$19=0,"—",$Q$24&"/100") | E18: =IF($Q$19=0,"— en attente de données",IF($Q$24=100,"Les provisions du mois sont couvertes par la trésorerie.","La trésorerie ne couvre pas encore les provisions du mois.")) | H18: Recommandations générales, à titre indicatif. | P18: Résultat projeté fin d'année (run-rate) | Q18: =IFERROR(($Q$5-$Q$6)/$Q$4*12,0)
P19: Données saisies ? (1 = oui) | Q19: =IF($Q$5+'💸 Dépenses'!$O$6=0,0,1)
B20: ANALYSES | P20: Score trésorerie /100 | Q20: =MIN(100,MAX(0,ROUND($Q$11/6*100,0)))
P21: Score rentabilité /100 | Q21: =MIN(100,MAX(0,ROUND($Q$12/0.2*100,0)))
P22: Score respect du budget /100 | Q22: =MIN(100,MAX(0,ROUND(100-MAX(0,$Q$13-1)*200,0)))
P23: Score dynamique CA /100 | Q23: =MIN(100,MAX(0,ROUND($Q$14*100,0)))
P24: Score provisions /100 | Q24: =IF($Q$9>=$Q$15,100,0)
P25: SCORE GLOBAL /100 | Q25: =ROUND(0.3*$Q$20+0.25*$Q$21+0.2*$Q$22+0.15*$Q$23+0.1*$Q$24,0)
P26: CA facturé TTC (année) | Q26: =SUM('💰 Recettes'!$H$10:$H$209)
P28: ='📋 Budget'!$B$16 | Q28: =SUMIFS('💸 Dépenses'!$F$10:$F$309,'💸 Dépenses'!$D$10:$D$309,$P28)+(ROW()-27)/1000000
P29: ='📋 Budget'!$B$17 | Q29: =SUMIFS('💸 Dépenses'!$F$10:$F$309,'💸 Dépenses'!$D$10:$D$309,$P29)+(ROW()-27)/1000000
P30: ='📋 Budget'!$B$18 | Q30: =SUMIFS('💸 Dépenses'!$F$10:$F$309,'💸 Dépenses'!$D$10:$D$309,$P30)+(ROW()-27)/1000000
P31: ='📋 Budget'!$B$19 | Q31: =SUMIFS('💸 Dépenses'!$F$10:$F$309,'💸 Dépenses'!$D$10:$D$309,$P31)+(ROW()-27)/1000000
P32: ='📋 Budget'!$B$20 | Q32: =SUMIFS('💸 Dépenses'!$F$10:$F$309,'💸 Dépenses'!$D$10:$D$309,$P32)+(ROW()-27)/1000000
P33: ='📋 Budget'!$B$21 | Q33: =SUMIFS('💸 Dépenses'!$F$10:$F$309,'💸 Dépenses'!$D$10:$D$309,$P33)+(ROW()-27)/1000000
P34: ='📋 Budget'!$B$22 | Q34: =SUMIFS('💸 Dépenses'!$F$10:$F$309,'💸 Dépenses'!$D$10:$D$309,$P34)+(ROW()-27)/1000000
P35: ='📋 Budget'!$B$23 | Q35: =SUMIFS('💸 Dépenses'!$F$10:$F$309,'💸 Dépenses'!$D$10:$D$309,$P35)+(ROW()-27)/1000000
P36: ='📋 Budget'!$B$24 | Q36: =SUMIFS('💸 Dépenses'!$F$10:$F$309,'💸 Dépenses'!$D$10:$D$309,$P36)+(ROW()-27)/1000000
P37: ='📋 Budget'!$B$25 | Q37: =SUMIFS('💸 Dépenses'!$F$10:$F$309,'💸 Dépenses'!$D$10:$D$309,$P37)+(ROW()-27)/1000000
B38: PRÉVISIONNEL vs RÉALISÉ — CUMUL ANNUEL | I38: TOP 5 DES DÉPENSES DE L'ANNÉE | P38: ='📋 Budget'!$B$26 | Q38: =SUMIFS('💸 Dépenses'!$F$10:$F$309,'💸 Dépenses'!$D$10:$D$309,$P38)+(ROW()-27)/1000000
C39: Prévu | D39: Réalisé | E39: Écart | F39: Écart % | G39: Tendance | H39: Progression | I39: Catégorie | K39: Montant | L39: Poids | P39: ='📋 Budget'!$B$27 | Q39: =SUMIFS('💸 Dépenses'!$F$10:$F$309,'💸 Dépenses'!$D$10:$D$309,$P39)+(ROW()-27)/1000000
B40: Recettes | C40: ='📋 Budget'!$O$12 | D40: ='📊 Suivi mensuel'!$D$19 | E40: =D40-C40 | F40: =IFERROR(E40/C40,0) | G40: =IF(E40>=0,"▲","▼") | H40: =REPT("█",ROUND(MIN(1,MAX(0,IFERROR(D40/C40,0)))*10,0))&REPT("░",10-ROUND(MIN(1,MAX(0,IFERROR(D40/C40,0)))*10,0)) | I40: =IFERROR(IF(LARGE($Q$28:$Q$42,1)<0.005,"—",INDEX($P$28:$P$42,MATCH(LARGE($Q$28:$Q$42,1),$Q$28:$Q$42,0))),"—") | K40: =IFERROR(ROUND(LARGE($Q$28:$Q$42,1),0),0) | L40: =IFERROR(IF(MAX($Q$28:$Q$42)<0.005,"",REPT("█",ROUND(LARGE($Q$28:$Q$42,1)/MAX($Q$28:$Q$42)*10,0))&REPT("░",10-ROUND(LARGE($Q$28:$Q$42,1)/MAX($Q$28:$Q$42)*10,0))),"") | P40: ='📋 Budget'!$B$28 | Q40: =SUMIFS('💸 Dépenses'!$F$10:$F$309,'💸 Dépenses'!$D$10:$D$309,$P40)+(ROW()-27)/1000000
B41: Dépenses | C41: ='📋 Budget'!$O$31 | D41: ='📊 Suivi mensuel'!$G$19 | E41: =C41-D41 | F41: =IFERROR(E41/C41,0) | G41: =IF(E41>=0,"▲","▼") | H41: =REPT("█",ROUND(MIN(1,MAX(0,IFERROR(D41/C41,0)))*10,0))&REPT("░",10-ROUND(MIN(1,MAX(0,IFERROR(D41/C41,0)))*10,0)) | I41: =IFERROR(IF(LARGE($Q$28:$Q$42,2)<0.005,"—",INDEX($P$28:$P$42,MATCH(LARGE($Q$28:$Q$42,2),$Q$28:$Q$42,0))),"—") | K41: =IFERROR(ROUND(LARGE($Q$28:$Q$42,2),0),0) | L41: =IFERROR(IF(MAX($Q$28:$Q$42)<0.005,"",REPT("█",ROUND(LARGE($Q$28:$Q$42,2)/MAX($Q$28:$Q$42)*10,0))&REPT("░",10-ROUND(LARGE($Q$28:$Q$42,2)/MAX($Q$28:$Q$42)*10,0))),"") | P41: ='📋 Budget'!$B$29 | Q41: =SUMIFS('💸 Dépenses'!$F$10:$F$309,'💸 Dépenses'!$D$10:$D$309,$P41)+(ROW()-27)/1000000
...

Sheet 🚀 Démarrer ici
A1: 🚀 DÉMARRER ICI
A2: Bienvenue dans votre assistant de pilotage. En 15 minutes, votre entreprise est configurée.
B3: 💡 Suivez les 5 étapes dans l'ordre, cochez-les au fur et à mesure (menu déroulant à droite), puis revenez ici chaque fin de mois pour votre routine de 10 minutes.
B4: ="Configuration : "&COUNTIF($I$7:$I$19,"✅")&"/5 étapes ✅"
B7: 1 | C7: Configurez votre entreprise | I7: ☐
C8: Ouvrez l'onglet ⚙️ Paramètres et renseignez les 8 informations : nom, forme juridique, année, solde de départ, régime de TVA, statut du dirigeant, salaire net mensuel et CFE estimée. C'est le moteur de tout le fichier.
B10: 2 | C10: Posez votre budget | I10: ☐
C11: Remplissez le 📋 Budget prévisionnel, mois par mois. Astuce : pas d'idée précise ? Commencez large, vous ajusterez en cours d'année.
B13: 3 | C13: Saisissez au fil de l'eau | I13: ☐
C14: Chaque facture dans 💰 Recettes, chaque achat dans 💸 Dépenses. Règle d'or : 5 minutes par semaine suffisent pour rester à jour.
B16: 4 | C16: Suivez vos trajets | I16: ☐
C17: À chaque déplacement professionnel, notez la date, le motif et les kilomètres dans 🚗 Indemnités KM. Ce sont des remboursements que beaucoup oublient.
B19: 5 | C19: Pilotez | I19: ☐
C20: Ouvrez le 🏠 Dashboard : score de santé, alertes, recommandations et 📅 Échéancier font le reste. Vous savez toujours où vous en êtes.
B22: ⏱️ VOTRE ROUTINE MENSUELLE EN 10 MINUTES
B23: ◻ Toutes les factures et toutes les dépenses du mois sont saisies.
B24: ◻ Les encaissements sont pointés (colonne « Encaissé » des 💰 Recettes).
B25: ◻ La TVA du mois est vérifiée dans 🧾 TVA & Impôts.
B26: ◻ Les provisions (URSSAF, IS, CFE) sont disponibles sur le compte.
B27: ◻ Les écarts du 📊 Suivi mensuel sont analysés (favorable ou non ?).
B28: ◻ La trésorerie du mois prochain est vérifiée dans 🏦 Trésorerie.
B30: ❓ Une question ? L'onglet 📖 Lexique vous explique tous les termes (TVA, IS, runway, provision…) en langage simple, avec des exemples concrets.

Sheet ⚙️ Paramètres
A1: ⚙️ PARAMÈTRES
A2: En clair : la fiche d'identité de votre gestion — remplie une fois, utilisée par tous les onglets.
B3: 💡 Remplissez uniquement les cellules crème. Elles alimentent automatiquement tous les autres onglets : ne modifiez ni l'ordre des listes ni le barème sans raison.
B5: Identité de l'entreprise | E5: Impôt sur les sociétés (taux modifiables)
B6: Nom de l'entreprise | C6: Astuce Conseil | E6: Seuil du taux réduit | F6: 42500
B7: Forme juridique | C7: SASU | E7: Taux réduit (PME) | F7: 0.15
B8: Année de gestion | C8: 2026 | E8: Taux normal | F8: 0.25
B9: Solde de trésorerie au 01/01 | C9: 12500 | E9: Taux réduit sous conditions PME (CA < 10 M€, capital détenu à 75 % par des personnes physiques) — valeurs indicatives.
B11: TVA & fiscalité | E11: Barème kilométrique — voitures (modifiable)
B12: Régime de TVA | C12: Réel normal | E12: Puissance fiscale | F12: ≤ 5 000 km (×) | G12: 5 001 à 20 000 km (×) | H12: 5 001 à 20 000 km (+) | I12: > 20 000 km (×)
B13: Taux de TVA par défaut | C13: 0.2 | E13: 3 CV et moins | F13: 0.529 | G13: 0.316 | H13: 1065 | I13: 0.37
B14: CFE estimée (annuelle) | C14: 650 | E14: 4 CV | F14: 0.606 | G14: 0.34 | H14: 1330 | I14: 0.407
E15: 5 CV | F15: 0.636 | G15: 0.357 | H15: 1395 | I15: 0.427
B16: Dirigeant & cotisations sociales | E16: 6 CV | F16: 0.665 | G16: 0.374 | H16: 1457 | I16: 0.447
B17: Statut du dirigeant | C17: Assimilé salarié (SASU) | E17: 7 CV et plus | F17: 0.697 | G17: 0.394 | H17: 1515 | I17: 0.47
B18: Taux de charges — Assimilé salarié (SASU) | C18: 0.82
B19: Taux de charges — TNS gérant majoritaire (SARL) | C19: 0.45
B20: Salaire net mensuel versé | C20: 2600 | E20: Listes de référence (menus déroulants — ne pas déplacer)
B21: Taux de charges appliqué (auto, selon le statut) | C21: =IF($C$17="Assimilé salarié (SASU)",$C$18,$C$19) | E21: Taux de TVA | F21: 0.2 | G21: Les catégories de dépenses des menus déroulants sont celles de l'onglet 📋 Budget (colonne Catégorie).
B22: Taux moyens indicatifs, à ajuster selon votre situation. | F22: 0.1
F23: 0.055
B24: Échéancier & simulateurs | F24: 0.021
B25: Jour de prélèvement URSSAF (5 ou 15) | C25: 5 | F25: 0
B26: Flat tax sur dividendes (PFU) | C26: 0.3
B27: Acompte TVA de juillet (réel simplifié) | C27: 0.55
B28: Acompte TVA de décembre (réel simplifié) | C28: 0.4
B29: Jours et taux usuels, à ajuster selon votre situation.

Sheet 📋 Budget
A1: 📋 BUDGET PRÉVISIONNEL
A2: En clair : ce que vous prévoyez de gagner et de dépenser — votre feuille de route de l'année.
B3: 💡 Saisissez vos prévisions dans les cellules crème (catégories personnalisables). Le salaire du dirigeant et ses charges sont pré-remplis depuis l'onglet ⚙️ Paramètres — vous pouvez les écraser.
B5: RECETTES PRÉVUES
B6: Catégorie | C6: Janv | D6: Févr | E6: Mars | F6: Avr | G6: Mai | H6: Juin | I6: Juil | J6: Août | K6: Sept | L6: Oct | M6: Nov | N6: Déc | O6: Total
B7: Prestations de conseil | C7: 6500 | D7: 7000 | E7: 7000 | F7: 7500 | G7: 7500 | H7: 8000 | I7: 6000 | J7: 4500 | K7: 8000 | L7: 8500 | M7: 8500 | N7: 7500 | O7: =SUM(C7:N7)
B8: Formations | C8: 1200 | D8: 0 | E8: 2400 | F8: 1200 | G8: 0 | H8: 2400 | I8: 0 | J8: 0 | K8: 2400 | L8: 1200 | M8: 0 | N8: 1200 | O8: =SUM(C8:N8)
B9: Ateliers & séminaires | C9: 0 | D9: 800 | E9: 0 | F9: 800 | G9: 0 | H9: 800 | I9: 0 | J9: 0 | K9: 800 | L9: 0 | M9: 800 | N9: 0 | O9: =SUM(C9:N9)
B10: Commissions & apport d'affaires | C10: 150 | D10: 150 | E10: 150 | F10: 150 | G10: 150 | H10: 150 | I10: 150 | J10: 150 | K10: 150 | L10: 150 | M10: 150 | N10: 150 | O10: =SUM(C10:N10)
B11: Autres recettes | C11: 0 | D11: 0 | E11: 0 | F11: 0 | G11: 0 | H11: 0 | I11: 0 | J11: 0 | K11: 0 | L11: 0 | M11: 0 | N11: 0 | O11: =SUM(C11:N11)
B12: Total recettes prévues | C12: =SUM(C7:C11) | D12: =SUM(D7:D11) | E12: =SUM(E7:E11) | F12: =SUM(F7:F11) | G12: =SUM(G7:G11) | H12: =SUM(H7:H11) | I12: =SUM(I7:I11) | J12: =SUM(J7:J11) | ... O12: =SUM(O7:O11)
B14: DÉPENSES PRÉVUES
B15: Catégorie | C15: Janv | D15: Févr | E15: Mars | F15: Avr | G15: Mai | H15: Juin | I15: Juil | J15: Août | K15: Sept | L15: Oct | M15: Nov | N15: Déc | O15: Total
B16: Achats & fournitures | C16: 120 | D16: 120 | E16: 120 | F16: 120 | G16: 120 | H16: 120 | I16: 120 | J16: 120 | K16: 120 | L16: 120 | M16: 120 | N16: 120 | O16: =SUM(C16:N16)
B17: Sous-traitance | C17: 400 | D17: 400 | E17: 600 | F17: 400 | G17: 400 | H17: 600 | I17: 200 | J17: 0 | K17: 600 | L17: 400 | M17: 400 | N17: 600 | O17: =SUM(C17:N17)
B18: Loyer & charges | C18: 350 | D18: 350 | E18: 350 | F18: 350 | G18: 350 | H18: 350 | I18: 350 | J18: 350 | K18: 350 | L18: 350 | M18: 350 | N18: 350 | O18: =SUM(C18:N18)
B19: Assurances | C19: 45 | D19: 45 | E19: 45 | F19: 45 | G19: 45 | H19: 45 | I19: 45 | J19: 45 | K19: 45 | L19: 45 | M19: 45 | N19: 45 | O19: =SUM(C19:N19)
B20: Télécom & internet | C20: 55 | D20: 55 | E20: 55 | F20: 55 | G20: 55 | H20: 55 | I20: 55 | J20: 55 | K20: 55 | L20: 55 | M20: 55 | N20: 55 | O20: =SUM(C20:N20)
B21: Logiciels & abonnements | C21: 130 | D21: 130 | E21: 130 | F21: 130 | G21: 130 | H21: 130 | I21: 130 | J21: 130 | K21: 130 | L21: 130 | M21: 130 | N21: 130 | O21: =SUM(C21:N21)
B22: Marketing & communication | C22: 250 | D22: 250 | E22: 250 | F22: 250 | G22: 250 | H22: 250 | I22: 250 | J22: 250 | K22: 250 | L22: 250 | M22: 250 | N22: 250 | O22: =SUM(C22:N22)
B23: Déplacements & missions | C23: 180 | D23: 180 | E23: 180 | F23: 180 | G23: 180 | H23: 180 | I23: 180 | J23: 180 | K23: 180 | L23: 180 | M23: 180 | N23: 180 | O23: =SUM(C23:N23)
B24: Salaire net dirigeant | C24: =SALAIRE_NET | D24: =SALAIRE_NET | E24: =SALAIRE_NET | F24: =SALAIRE_NET | G24: =SALAIRE_NET | H24: =SALAIRE_NET | I24: =SALAIRE_NET | J24: =SALAIRE_NET | ... N24: =SALAIRE_NET | O24: =SUM(C24:N24)
B25: Charges sociales dirigeant | C25: =ROUND(SALAIRE_NET*TAUX_CHARGES,0) | D25: =ROUND(SALAIRE_NET*TAUX_CHARGES,0) | E25: =ROUND(SALAIRE_NET*TAUX_CHARGES,0) | F25: =ROUND(SALAIRE_NET*TAUX_CHARGES,0) | G25: =ROUND(SALAIRE_NET*TAUX_CHARGES,0) | H25: =ROUND(SALAIRE_NET*TAUX_CHARGES,0) | I25: =ROUND(SALAIRE_NET*TAUX_CHARGES,0) | J25: =ROUND(SALAIRE_NET*TAUX_CHARGES,0) | ... N25: =ROUND(SALAIRE_NET*TAUX_CHARGES,0) | O25: =SUM(C25:N25)
B26: Honoraires comptables | C26: 120 | D26: 120 | E26: 120 | F26: 120 | G26: 120 | H26: 120 | I26: 120 | J26: 120 | K26: 120 | L26: 120 | M26: 120 | N26: 120 | O26: =SUM(C26:N26)
B27: Frais bancaires | C27: 29 | D27: 29 | E27: 29 | F27: 29 | G27: 29 | H27: 29 | I27: 29 | J27: 29 | K27: 29 | L27: 29 | M27: 29 | N27: 29 | O27: =SUM(C27:N27)
B28: Formation | C28: 0 | D28: 0 | E28: 0 | F28: 800 | G28: 0 | H28: 0 | I28: 0 | J28: 0 | K28: 0 | L28: 600 | M28: 0 | N28: 0 | O28: =SUM(C28:N28)
B29: Entretien & petit équipement | C29: 40 | D29: 40 | E29: 40 | F29: 40 | G29: 40 | H29: 40 | I29: 40 | J29: 40 | K29: 40 | L29: 40 | M29: 40 | N29: 40 | O29: =SUM(C29:N29)
B30: Divers & imprévus | C30: 100 | D30: 100 | E30: 100 | F30: 100 | G30: 100 | H30: 100 | I30: 100 | J30: 100 | K30: 100 | L30: 100 | M30: 100 | N30: 100 | O30: =SUM(C30:N30)
B31: Total dépenses prévues | C31: =SUM(C16:C30) | D31: =SUM(D16:D30) | E31: =SUM(E16:E30) | F31: =SUM(F16:F30) | G31: =SUM(G16:G30) | H31: =SUM(H16:H30) | I31: =SUM(I16:I30) | J31: =SUM(J16:J30) | ... O31: =SUM(O16:O30)
B33: Résultat prévisionnel mensuel | C33: =C12-C31 | D33: =D12-D31 | E33: =E12-E31 | F33: =F12-F31 | G33: =G12-G31 | H33: =H12-H31 | I33: =I12-I31 | J33: =J12-J31 | ... O33: =O12-O31
B34: Résultat prévisionnel cumulé | C34: =C33 | D34: =C34+D33 | E34: =D34+E33 | F34: =E34+F33 | G34: =F34+G33 | H34: =G34+H33 | I34: =H34+I33 | J34: =I34+J33 | K34: =J34+K33 | ... N34: =M34+N33 | O34: =N34

Sheet 💰 Recettes
A1: 💰 RECETTES
A2: En clair : tout ce que vous facturez à vos clients — la source de votre chiffre d'affaires.
B3: 💡 Une ligne par facture : remplissez les cellules crème (date, client, description, montant HT, taux de TVA, encaissé). Les dix premières lignes sont des exemples à remplacer par vos données.
B5: Synthèse mensuelle | C5: Janv | D5: Févr | E5: Mars | F5: Avr | G5: Mai | H5: Juin | I5: Juil | J5: Août | K5: Sept | L5: Oct | M5: Nov | N5: Déc | O5: Année
B6: Facturé HT | C6: =SUMIFS($E$10:$E$209,$J$10:$J$209,1) | D6: =SUMIFS($E$10:$E$209,$J$10:$J$209,2) | E6: =SUMIFS($E$10:$E$209,$J$10:$J$209,3) | F6: =SUMIFS($E$10:$E$209,$J$10:$J$209,4) | G6: =SUMIFS($E$10:$E$209,$J$10:$J$209,5) | H6: =SUMIFS($E$10:$E$209,$J$10:$J$209,6) | I6: =SUMIFS($E$10:$E$209,$J$10:$J$209,7) | J6: =SUMIFS($E$10:$E$209,$J$10:$J$209,8) | K6: =SUMIFS($E$10:$E$209,$J$10:$J$209,9) | L6: =SUMIFS($E$10:$E$209,$J$10:$J$209,10) | M6: =SUMIFS($E$10:$E$209,$J$10:$J$209,11) | N6: =SUMIFS($E$10:$E$209,$J$10:$J$209,12) | O6: =SUM(C6:N6)
B7: Encaissé TTC | C7: =SUMIFS($H$10:$H$209,$J$10:$J$209,1,$I$10:$I$209,"Oui") | D7: =SUMIFS($H$10:$H$209,$J$10:$J$209,2,$I$10:$I$209,"Oui") | E7: =SUMIFS($H$10:$H$209,$J$10:$J$209,3,$I$10:$I$209,"Oui") | F7: =SUMIFS($H$10:$H$209,$J$10:$J$209,4,$I$10:$I$209,"Oui") | G7: =SUMIFS($H$10:$H$209,$J$10:$J$209,5,$I$10:$I$209,"Oui") | H7: =SUMIFS($H$10:$H$209,$J$10:$J$209,6,$I$10:$I$209,"Oui") | I7: =SUMIFS($H$10:$H$209,$J$10:$J$209,7,$I$10:$I$209,"Oui") | J7: =SUMIFS($H$10:$H$209,$J$10:$J$209,8,$I$10:$I$209,"Oui") | K7: =SUMIFS($H$10:$H$209,$J$10:$J$209,9,$I$10:$I$209,"Oui") | L7: =SUMIFS($H$10:$H$209,$J$10:$J$209,10,$I$10:$I$209,"Oui") | M7: =SUMIFS($H$10:$H$209,$J$10:$J$209,11,$I$10:$I$209,"Oui") | N7: =SUMIFS($H$10:$H$209,$J$10:$J$209,12,$I$10:$I$209,"Oui") | O7: =SUM(C7:N7)
B9: Date | C9: Client | D9: Description | E9: Montant HT | F9: Taux TVA | G9: TVA | H9: Montant TTC | I9: Encaissé | J9: Mois
B10: 46030 | C10: Studio Novelli | D10: Audit organisation & process | E10: 3200 | F10: 0.2 | G10: =IF(OR($E10="",$F10=""),"",ROUND($E10*$F10,2)) | H10: =IF($E10="","",ROUND($E10*(1+IF($F10="",0,$F10)),2)) | I10: Oui | J10: =IF($B10="","",MONTH($B10))
B11: 46037 | C11: Boulangerie Martin | D11: Accompagnement digitalisation | E11: 1450 | F11: 0.2 | G11: =IF(OR($E11="",$F11=""),"",ROUND($E11*$F11,2)) | H11: =IF($E11="","",ROUND($E11*(1+IF($F11="",0,$F11)),2)) | I11: Oui | J11: =IF($B11="","",MONTH($B11))
B12: 46044 | C12: Mairie de Beaulieu | D12: Formation gestion de projet (2 j) | E12: 2400 | F12: 0.2 | G12: =IF(OR($E12="",$F12=""),"",ROUND($E12*$F12,2)) | H12: =IF($E12="","",ROUND($E12*(1+IF($F12="",0,$F12)),2)) | I12: Oui | J12: =IF($B12="","",MONTH($B12))
B13: 46052 | C13: Cabinet Ferrand | D13: Conseil stratégie — forfait janvier | E13: 1800 | F13: 0.2 | G13: =IF(OR($E13="",$F13=""),"",ROUND($E13*$F13,2)) | H13: =IF($E13="","",ROUND($E13*(1+IF($F13="",0,$F13)),2)) | I13: Oui | J13: =IF($B13="","",MONTH($B13))
B14: 46059 | C14: Studio Novelli | D14: Suivi mensuel — février | E14: 950 | F14: 0.2 | G14: =IF(OR($E14="",$F14=""),"",ROUND($E14*$F14,2)) | H14: =IF($E14="","",ROUND($E14*(1+IF($F14="",0,$F14)),2)) | I14: Oui | J14: =IF($B14="","",MONTH($B14))
B15: 46065 | C15: Éditions Clairval | D15: Atelier productivité équipe | E15: 1600 | F15: 0.2 | G15: =IF(OR($E15="",$F15=""),"",ROUND($E15*$F15,2)) | H15: =IF($E15="","",ROUND($E15*(1+IF($F15="",0,$F15)),2)) | I15: Oui | J15: =IF($B15="","",MONTH($B15))
B16: 46073 | C16: Boutique Léonie | D16: Refonte parcours client | E16: 2750 | F16: 0.2 | G16: =IF(OR($E16="",$F16=""),"",ROUND($E16*$F16,2)) | H16: =IF($E16="","",ROUND($E16*(1+IF($F16="",0,$F16)),2)) | I16: Non | J16: =IF($B16="","",MONTH($B16))
B17: 46080 | C17: Cabinet Ferrand | D17: Conseil stratégie — forfait février | E17: 1800 | F17: 0.2 | G17: =IF(OR($E17="",$F17=""),"",ROUND($E17*$F17,2)) | H17: =IF($E17="","",ROUND($E17*(1+IF($F17="",0,$F17)),2)) | I17: Oui | J17: =IF($B17="","",MONTH($B17))
B18: 46091 | C18: Groupe Vaillant | D18: Diagnostic flash + restitution | E18: 3900 | F18: 0.2 | G18: =IF(OR($E18="",$F18=""),"",ROUND($E18*$F18,2)) | H18: =IF($E18="","",ROUND($E18*(1+IF($F18="",0,$F18)),2)) | I18: Non | J18: =IF($B18="","",MONTH($B18))
B19: 46099 | C19: Mairie de Beaulieu | D19: Formation bureautique (1 j) | E19: 1200 | F19: 0.2 | G19: =IF(OR($E19="",$F19=""),"",ROUND($E19*$F19,2)) | H19: =IF($E19="","",ROUND($E19*(1+IF($F19="",0,$F19)),2)) | I19: Non | J19: =IF($B19="","",MONTH($B19))
G20: =IF(OR($E20="",$F20=""),"",ROUND($E20*$F20,2)) | H20: =IF($E20="","",ROUND($E20*(1+IF($F20="",0,$F20)),2)) | J20: =IF($B20="","",MONTH($B20))
G21: =IF(OR($E21="",$F21=""),"",ROUND($E21*$F21,2)) | H21: =IF($E21="","",ROUND($E21*(1+IF($F21="",0,$F21)),2)) | J21: =IF($B21="","",MONTH($B21))
G22: =IF(OR($E22="",$F22=""),"",ROUND($E22*$F22,2)) | H22: =IF($E22="","",ROUND($E22*(1+IF($F22="",0,$F22)),2)) | J22: =IF($B22="","",MONTH($B22))
G23: =IF(OR($E23="",$F23=""),"",ROUND($E23*$F23,2)) | H23: =IF($E23="","",ROUND($E23*(1+IF($F23="",0,$F23)),2)) | J23: =IF($B23="","",MONTH($B23))
G24: =IF(OR($E24="",$F24=""),"",ROUND($E24*$F24,2)) | H24: =IF($E24="","",ROUND($E24*(1+IF($F24="",0,$F24)),2)) | J24: =IF($B24="","",MONTH($B24))
G25: =IF(OR($E25="",$F25=""),"",ROUND($E25*$F25,2)) | H25: =IF($E25="","",ROUND($E25*(1+IF($F25="",0,$F25)),2)) | J25: =IF($B25="","",MONTH($B25))
G26: =IF(OR($E26="",$F26=""),"",ROUND($E26*$F26,2)) | H26: =IF($E26="","",ROUND($E26*(1+IF($F26="",0,$F26)),2)) | J26: =IF($B26="","",MONTH($B26))
G27: =IF(OR($E27="",$F27=""),"",ROUND($E27*$F27,2)) | H27: =IF($E27="","",ROUND($E27*(1+IF($F27="",0,$F27)),2)) | J27: =IF($B27="","",MONTH($B27))
G28: =IF(OR($E28="",$F28=""),"",ROUND($E28*$F28,2)) | H28: =IF($E28="","",ROUND($E28*(1+IF($F28="",0,$F28)),2)) | J28: =IF($B28="","",MONTH($B28))
G29: =IF(OR($E29="",$F29=""),"",ROUND($E29*$F29,2)) | H29: =IF($E29="","",ROUND($E29*(1+IF($F29="",0,$F29)),2)) | J29: =IF($B29="","",MONTH($B29))
G30: =IF(OR($E30="",$F30=""),"",ROUND($E30*$F30,2)) | H30: =IF($E30="","",ROUND($E30*(1+IF($F30="",0,$F30)),2)) | J30: =IF($B30="","",MONTH($B30))
G31: =IF(OR($E31="",$F31=""),"",ROUND($E31*$F31,2)) | H31: =IF($E31="","",ROUND($E31*(1+IF($F31="",0,$F31)),2)) | J31: =IF($B31="","",MONTH($B31))
... G209: =IF(OR($E209="",$F209=""),"",ROUND($E209*$F209,2)) | H209: =IF($E209="","",ROUND($E209*(1+IF($F209="",0,$F209)),2)) | J209: =IF($B209="","",MONTH($B209))

Sheet 💸 Dépenses
A1: 💸 DÉPENSES
A2: En clair : tout ce que l'entreprise dépense — pour garder la main sur vos coûts.
B3: 💡 Choisissez la catégorie dans le menu déroulant (liste de l'onglet 📋 Budget). Ne saisissez pas ici le salaire du dirigeant, les cotisations, la TVA ou les impôts : ils sont gérés automatiquement dans 🏦 Trésorerie et 🧾 TVA & Impôts.
B5: Synthèse mensuelle | C5: Janv | D5: Févr | E5: Mars | F5: Avr | G5: Mai | H5: Juin | I5: Juil | J5: Août | K5: Sept | L5: Oct | M5: Nov | N5: Déc | O5: Année
B6: Dépenses HT | C6: =SUMIFS($F$10:$F$309,$K$10:$K$309,1) | D6: =SUMIFS($F$10:$F$309,$K$10:$K$309,2) | E6: =SUMIFS($F$10:$F$309,$K$10:$K$309,3) | F6: =SUMIFS($F$10:$F$309,$K$10:$K$309,4) | G6: =SUMIFS($F$10:$F$309,$K$10:$K$309,5) | H6: =SUMIFS($F$10:$F$309,$K$10:$K$309,6) | I6: =SUMIFS($F$10:$F$309,$K$10:$K$309,7) | J6: =SUMIFS($F$10:$F$309,$K$10:$K$309,8) | K6: =SUMIFS($F$10:$F$309,$K$10:$K$309,9) | L6: =SUMIFS($F$10:$F$309,$K$10:$K$309,10) | M6: =SUMIFS($F$10:$F$309,$K$10:$K$309,11) | N6: =SUMIFS($F$10:$F$309,$K$10:$K$309,12) | O6: =SUM(C6:N6)
B7: Payées TTC | C7: =SUMIFS($I$10:$I$309,$K$10:$K$309,1,$J$10:$J$309,"Oui") | D7: =SUMIFS($I$10:$I$309,$K$10:$K$309,2,$J$10:$J$309,"Oui") | E7: =SUMIFS($I$10:$I$309,$K$10:$K$309,3,$J$10:$J$309,"Oui") | F7: =SUMIFS($I$10:$I$309,$K$10:$K$309,4,$J$10:$J$309,"Oui") | G7: =SUMIFS($I$10:$I$309,$K$10:$K$309,5,$J$10:$J$309,"Oui") | H7: =SUMIFS($I$10:$I$309,$K$10:$K$309,6,$J$10:$J$309,"Oui") | I7: =SUMIFS($I$10:$I$309,$K$10:$K$309,7,$J$10:$J$309,"Oui") | J7: =SUMIFS($I$10:$I$309,$K$10:$K$309,8,$J$10:$J$309,"Oui") | K7: =SUMIFS($I$10:$I$309,$K$10:$K$309,9,$J$10:$J$309,"Oui") | L7: =SUMIFS($I$10:$I$309,$K$10:$K$309,10,$J$10:$J$309,"Oui") | M7: =SUMIFS($I$10:$I$309,$K$10:$K$309,11,$J$10:$J$309,"Oui") | N7: =SUMIFS($I$10:$I$309,$K$10:$K$309,12,$J$10:$J$309,"Oui") | O7: =SUM(C7:N7)
B9: Date | C9: Fournisseur | D9: Catégorie | E9: Description | F9: Montant HT | G9: Taux TVA | H9: TVA déductible | I9: Montant TTC | J9: Payé | K9: Mois
B10: 46027 | C10: OVHcloud | D10: Logiciels & abonnements | E10: Hébergement site + e-mails | F10: 14.9 | G10: 0.2 | H10: =IF(OR($F10="",$G10=""),"",ROUND($F10*$G10,2)) | I10: =IF($F10="","",ROUND($F10*(1+IF($G10="",0,$G10)),2)) | J10: Oui | K10: =IF($B10="","",MONTH($B10))
B11: 46027 | C11: AXA Pro | D11: Assurances | E11: RC Pro — prime mensuelle | F11: 38.5 | G11: 0 | H11: =IF(OR($F11="",$G11=""),"",ROUND($F11*$G11,2)) | I11: =IF($F11="","",ROUND($F11*(1+IF($G11="",0,$G11)),2)) | J11: Oui | K11: =IF($B11="","",MONTH($B11))
B12: 46031 | C12: SNCF Connect | D12: Déplacements & missions | E12: AR Paris — réunion client | F12: 89 | G12: 0.1 | H12: =IF(OR($F12="",$G12=""),"",ROUND($F12*$G12,2)) | I12: =IF($F12="","",ROUND($F12*(1+IF($G12="",0,$G12)),2)) | J12: Oui | K12: =IF($B12="","",MONTH($B12))
B13: 46034 | C13: Adobe | D13: Logiciels & abonnements | E13: Creative Cloud | F13: 59.99 | G13: 0.2 | H13: =IF(OR($F13="",$G13=""),"",ROUND($F13*$G13,2)) | I13: =IF($F13="","",ROUND($F13*(1+IF($G13="",0,$G13)),2)) | J13: Oui | K13: =IF($B13="","",MONTH($B13))
B14: 46037 | C14: Compta Facile | D14: Honoraires comptables | E14: Forfait comptable janvier | F14: 120 | G14: 0.2 | H14: =IF(OR($F14="",$G14=""),"",ROUND($F14*$G14,2)) | I14: =IF($F14="","",ROUND($F14*(1+IF($G14="",0,$G14)),2)) | J14: Oui | K14: =IF($B14="","",MONTH($B14))
B15: 46042 | C15: Orange Pro | D15: Télécom & internet | E15: Forfait mobile + fibre | F15: 54.9 | G15: 0.2 | H15: =IF(OR($F15="",$G15=""),"",ROUND($F15*$G15,2)) | I15: =IF($F15="","",ROUND($F15*(1+IF($G15="",0,$G15)),2)) | J15: Oui | K15: =IF($B15="","",MONTH($B15))
B16: 46050 | C16: Qonto | D16: Frais bancaires | E16: Abonnement compte pro | F16: 29 | G16: 0.2 | H16: =IF(OR($F16="",$G16=""),"",ROUND($F16*$G16,2)) | I16: =IF($F16="","",ROUND($F16*(1+IF($G16="",0,$G16)),2)) | J16: Oui | K16: =IF($B16="","",MONTH($B16))
B17: 46056 | C17: Bureau Vallée | D17: Achats & fournitures | E17: Papeterie & consommables | F17: 47.6 | G17: 0.2 | H17: =IF(OR($F17="",$G17=""),"",ROUND($F17*$G17,2)) | I17: =IF($F17="","",ROUND($F17*(1+IF($G17="",0,$G17)),2)) | J17: Oui | K17: =IF($B17="","",MONTH($B17))
B18: 46063 | C18: Meta Ads | D18: Marketing & communication | E18: Campagne prospection février | F18: 150 | G18: 0.2 | H18: =IF(OR($F18="",$G18=""),"",ROUND($F18*$G18,2)) | I18: =IF($F18="","",ROUND($F18*(1+IF($G18="",0,$G18)),2)) | J18: Oui | K18: =IF($B18="","",MONTH($B18))
B19: 46071 | C19: La Poste | D19: Achats & fournitures | E19: Affranchissements | F19: 21.4 | G19: 0.2 | H19: =IF(OR($F19="",$G19=""),"",ROUND($F19*$G19,2)) | I19: =IF($F19="","",ROUND($F19*(1+IF($G19="",0,$G19)),2)) | J19: Non | K19: =IF($B19="","",MONTH($B19))
H20: =IF(OR($F20="",$G20=""),"",ROUND($F20*$G20,2)) | I20: =IF($F20="","",ROUND($F20*(1+IF($G20="",0,$G20)),2)) | K20: =IF($B20="","",MONTH($B20))
H21: =IF(OR($F21="",$G21=""),"",ROUND($F21*$G21,2)) | I21: =IF($F21="","",ROUND($F21*(1+IF($G21="",0,$G21)),2)) | K21: =IF($B21="","",MONTH($B21))
H22: =IF(OR($F22="",$G22=""),"",ROUND($F22*$G22,2)) | I22: =IF($F22="","",ROUND($F22*(1+IF($G22="",0,$G22)),2)) | K22: =IF($B22="","",MONTH($B22))
H23: =IF(OR($F23="",$G23=""),"",ROUND($F23*$G23,2)) | I23: =IF($F23="","",ROUND($F23*(1+IF($G23="",0,$G23)),2)) | K23: =IF($B23="","",MONTH($B23))
H24: =IF(OR($F24="",$G24=""),"",ROUND($F24*$G24,2)) | I24: =IF($F24="","",ROUND($F24*(1+IF($G24="",0,$G24)),2)) | K24: =IF($B24="","",MONTH($B24))
H25: =IF(OR($F25="",$G25=""),"",ROUND($F25*$G25,2)) | I25: =IF($F25="","",ROUND($F25*(1+IF($G25="",0,$G25)),2)) | K25: =IF($B25="","",MONTH($B25))
H26: =IF(OR($F26="",$G26=""),"",ROUND($F26*$G26,2)) | I26: =IF($F26="","",ROUND($F26*(1+IF($G26="",0,$G26)),2)) | K26: =IF($B26="","",MONTH($B26))
H27: =IF(OR($F27="",$G27=""),"",ROUND($F27*$G27,2)) | I27: =IF($F27="","",ROUND($F27*(1+IF($G27="",0,$G27)),2)) | K27: =IF($B27="","",MONTH($B27))
H28: =IF(OR($F28="",$G28=""),"",ROUND($F28*$G28,2)) | I28: =IF($F28="","",ROUND($F28*(1+IF($G28="",0,$G28)),2)) | K28: =IF($B28="","",MONTH($B28))
H29: =IF(OR($F29="",$G29=""),"",ROUND($F29*$G29,2)) | I29: =IF($F29="","",ROUND($F29*(1+IF($G29="",0,$G29)),2)) | K29: =IF($B29="","",MONTH($B29))
H30: =IF(OR($F30="",$G30=""),"",ROUND($F30*$G30,2)) | I30: =IF($F30="","",ROUND($F30*(1+IF($G30="",0,$G30)),2)) | K30: =IF($B30="","",MONTH($B30))
H31: =IF(OR($F31="",$G31=""),"",ROUND($F31*$G31,2)) | I31: =IF($F31="","",ROUND($F31*(1+IF($G31="",0,$G31)),2)) | K31: =IF($B31="","",MONTH($B31))
... H309: =IF(OR($F309="",$G309=""),"",ROUND($F309*$G309,2)) | I309: =IF($F309="","",ROUND($F309*(1+IF($G309="",0,$G309)),2)) | K309: =IF($B309="","",MONTH($B309))

Sheet 📊 Suivi mensuel
A1: 📊 SUIVI MENSUEL — PRÉVISIONNEL vs RÉALISÉ
A2: En clair : prévu contre réalisé — pour savoir si vous êtes sur la bonne trajectoire.
B3: 💡 Un écart positif est toujours favorable (vert) ; un écart négatif est défavorable (rouge). Les dépenses réalisées incluent automatiquement le salaire net + cotisations du dirigeant pour les mois écoulés.
C5: RECETTES | F5: DÉPENSES | I5: RÉSULTAT
B6: Mois | C6: Prévu | D6: Réalisé | E6: Écart | F6: Prévu | G6: Réalisé | H6: Écart | I6: Prévu | J6: Réalisé | K6: Écart
B7: Janv | C7: ='📋 Budget'!C12 | D7: =SUMIFS('💰 Recettes'!$E$10:$E$209,'💰 Recettes'!$J$10:$J$209,1) | E7: =D7-C7 | F7: ='📋 Budget'!C31 | G7: =SUMIFS('💸 Dépenses'!$F$10:$F$309,'💸 Dépenses'!$K$10:$K$309,1)+IF(OR(YEAR(TODAY())>ANNEE,AND(YEAR(TODAY())=ANNEE,MONTH(TODAY())>=1)),ROUND(SALAIRE_NET*(1+TAUX_CHARGES),2),0) | H7: =F7-G7 | I7: =C7-F7 | J7: =D7-G7 | K7: =J7-I7
B8: Févr | C8: ='📋 Budget'!D12 | D8: =SUMIFS('💰 Recettes'!$E$10:$E$209,'💰 Recettes'!$J$10:$J$209,2) | E8: =D8-C8 | F8: ='📋 Budget'!D31 | G8: =SUMIFS('💸 Dépenses'!$F$10:$F$309,'💸 Dépenses'!$K$10:$K$309,2)+IF(OR(YEAR(TODAY())>ANNEE,AND(YEAR(TODAY())=ANNEE,MONTH(TODAY())>=2)),ROUND(SALAIRE_NET*(1+TAUX_CHARGES),2),0) | H8: =F8-G8 | I8: =C8-F8 | J8: =D8-G8 | K8: =J8-I8
B9: Mars | C9: ='📋 Budget'!E12 | D9: =SUMIFS('💰 Recettes'!$E$10:$E$209,'💰 Recettes'!$J$10:$J$209,3) | E9: =D9-C9 | F9: ='📋 Budget'!E31 | G9: =SUMIFS('💸 Dépenses'!$F$10:$F$309,'💸 Dépenses'!$K$10:$K$309,3)+IF(OR(YEAR(TODAY())>ANNEE,AND(YEAR(TODAY())=ANNEE,MONTH(TODAY())>=3)),ROUND(SALAIRE_NET*(1+TAUX_CHARGES),2),0) | H9: =F9-G9 | I9: =C9-F9 | J9: =D9-G9 | K9: =J9-I9
B10: Avr | C10: ='📋 Budget'!F12 | D10: =SUMIFS('💰 Recettes'!$E$10:$E$209,'💰 Recettes'!$J$10:$J$209,4) | E10: =D10-C10 | F10: ='📋 Budget'!F31 | G10: =SUMIFS('💸 Dépenses'!$F$10:$F$309,'💸 Dépenses'!$K$10:$K$309,4)+IF(OR(YEAR(TODAY())>ANNEE,AND(YEAR(TODAY())=ANNEE,MONTH(TODAY())>=4)),ROUND(SALAIRE_NET*(1+TAUX_CHARGES),2),0) | H10: =F10-G10 | I10: =C10-F10 | J10: =D10-G10 | K10: =J10-I10
B11: Mai | C11: ='📋 Budget'!G12 | D11: =SUMIFS('💰 Recettes'!$E$10:$E$209,'💰 Recettes'!$J$10:$J$209,5) | E11: =D11-C11 | F11: ='📋 Budget'!G31 | G11: =SUMIFS('💸 Dépenses'!$F$10:$F$309,'💸 Dépenses'!$K$10:$K$309,5)+IF(OR(YEAR(TODAY())>ANNEE,AND(YEAR(TODAY())=ANNEE,MONTH(TODAY())>=5)),ROUND(SALAIRE_NET*(1+TAUX_CHARGES),2),0) | H11: =F11-G11 | I11: =C11-F11 | J11: =D11-G11 | K11: =J11-I11
B12: Juin | C12: ='📋 Budget'!H12 | D12: =SUMIFS('💰 Recettes'!$E$10:$E$209,'💰 Recettes'!$J$10:$J$209,6) | E12: =D12-C12 | F12: ='📋 Budget'!H31 | G12: =SUMIFS('💸 Dépenses'!$F$10:$F$309,'💸 Dépenses'!$K$10:$K$309,6)+IF(OR(YEAR(TODAY())>ANNEE,AND(YEAR(TODAY())=ANNEE,MONTH(TODAY())>=6)),ROUND(SALAIRE_NET*(1+TAUX_CHARGES),2),0) | H12: =F12-G12 | I12: =C12-F12 | J12: =D12-G12 | K12: =J12-I12
B13: Juil | C13: ='📋 Budget'!I12 | D13: =SUMIFS('💰 Recettes'!$E$10:$E$209,'💰 Recettes'!$J$10:$J$209,7) | E13: =D13-C13 | F13: ='📋 Budget'!I31 | G13: =SUMIFS('💸 Dépenses'!$F$10:$F$309,'💸 Dépenses'!$K$10:$K$309,7)+IF(OR(YEAR(TODAY())>ANNEE,AND(YEAR(TODAY())=ANNEE,MONTH(TODAY())>=7)),ROUND(SALAIRE_NET*(1+TAUX_CHARGES),2),0) | H13: =F13-G13 | I13: =C13-F13 | J13: =D13-G13 | K13: =J13-I13
B14: Août | C14: ='📋 Budget'!J12 | D14: =SUMIFS('💰 Recettes'!$E$10:$E$209,'💰 Recettes'!$J$10:$J$209,8) | E14: =D14-C14 | F14: ='📋 Budget'!J31 | G14: =SUMIFS('💸 Dépenses'!$F$10:$F$309,'💸 Dépenses'!$K$10:$K$309,8)+IF(OR(YEAR(TODAY())>ANNEE,AND(YEAR(TODAY())=ANNEE,MONTH(TODAY())>=8)),ROUND(SALAIRE_NET*(1+TAUX_CHARGES),2),0) | H14: =F14-G14 | I14: =C14-F14 | J14: =D14-G14 | K14: =J14-I14
B15: Sept | C15: ='📋 Budget'!K12 | D15: =SUMIFS('💰 Recettes'!$E$10:$E$209,'💰 Recettes'!$J$10:$J$209,9) | E15: =D15-C15 | F15: ='📋 Budget'!K31 | G15: =SUMIFS('💸 Dépenses'!$F$10:$F$309,'💸 Dépenses'!$K$10:$K$309,9)+IF(OR(YEAR(TODAY())>ANNEE,AND(YEAR(TODAY())=ANNEE,MONTH(TODAY())>=9)),ROUND(SALAIRE_NET*(1+TAUX_CHARGES),2),0) | H15: =F15-G15 | I15: =C15-F15 | J15: =D15-G15 | K15: =J15-I15
B16: Oct | C16: ='📋 Budget'!L12 | D16: =SUMIFS('💰 Recettes'!$E$10:$E$209,'💰 Recettes'!$J$10:$J$209,10) | E16: =D16-C16 | F16: ='📋 Budget'!L31 | G16: =SUMIFS('💸 Dépenses'!$F$10:$F$309,'💸 Dépenses'!$K$10:$K$309,10)+IF(OR(YEAR(TODAY())>ANNEE,AND(YEAR(TODAY())=ANNEE,MONTH(TODAY())>=10)),ROUND(SALAIRE_NET*(1+TAUX_CHARGES),2),0) | H16: =F16-G16 | I16: =C16-F16 | J16: =D16-G16 | K16: =J16-I16
B17: Nov | C17: ='📋 Budget'!M12 | D17: =SUMIFS('💰 Recettes'!$E$10:$E$209,'💰 Recettes'!$J$10:$J$209,11) | E17: =D17-C17 | F17: ='📋 Budget'!M31 | G17: =SUMIFS('💸 Dépenses'!$F$10:$F$309,'💸 Dépenses'!$K$10:$K$309,11)+IF(OR(YEAR(TODAY())>ANNEE,AND(YEAR(TODAY())=ANNEE,MONTH(TODAY())>=11)),ROUND(SALAIRE_NET*(1+TAUX_CHARGES),2),0) | H17: =F17-G17 | I17: =C17-F17 | J17: =D17-G17 | K17: =J17-I17
B18: Déc | C18: ='📋 Budget'!N12 | D18: =SUMIFS('💰 Recettes'!$E$10:$E$209,'💰 Recettes'!$J$10:$J$209,12) | E18: =D18-C18 | F18: ='📋 Budget'!N31 | G18: =SUMIFS('💸 Dépenses'!$F$10:$F$309,'💸 Dépenses'!$K$10:$K$309,12)+IF(OR(YEAR(TODAY())>ANNEE,AND(YEAR(TODAY())=ANNEE,MONTH(TODAY())>=12)),ROUND(SALAIRE_NET*(1+TAUX_CHARGES),2),0) | H18: =F18-G18 | I18: =C18-F18 | J18: =D18-G18 | K18: =J18-I18
B19: CUMUL | C19: =SUM(C7:C18) | D19: =SUM(D7:D18) | E19: =SUM(E7:E18) | F19: =SUM(F7:F18) | G19: =SUM(G7:G18) | H19: =SUM(H7:H18) | I19: =SUM(I7:I18) | J19: =SUM(J7:J18) | K19: =SUM(K7:K18)

Sheet 🏦 Trésorerie
A1: 🏦 PLAN DE TRÉSORERIE
A2: En clair : combien il y a réellement sur le compte, mois par mois — le nerf de la guerre.
B3: 💡 Seules les lignes « Autres encaissements » et « Autres décaissements » se saisissent ici. Le reste provient de vos recettes encaissées, dépenses payées, salaire, cotisations, TVA, IS et CFE. Solde négatif = fond rouge, solde < 1 000 € = fond orange.
C5: Janv | D5: Févr | E5: Mars | F5: Avr | G5: Mai | H5: Juin | I5: Juil | J5: Août | K5: Sept | L5: Oct | M5: Nov | N5: Déc | O5: Année
B6: Solde en début de mois | C6: =SOLDE_INIT | D6: =C20 | E6: =D20 | F6: =E20 | G6: =F20 | H6: =G20 | I6: =H20 | J6: =I20 | K6: =J20 | ... N6: =M20 | O6: =C6
B7: ENCAISSEMENTS
B8: Recettes encaissées (TTC) | C8: =SUMIFS('💰 Recettes'!$H$10:$H$209,'💰 Recettes'!$J$10:$J$209,1,'💰 Recettes'!$I$10:$I$209,"Oui") | D8: =SUMIFS('💰 Recettes'!$H$10:$H$209,'💰 Recettes'!$J$10:$J$209,2,'💰 Recettes'!$I$10:$I$209,"Oui") | E8: =SUMIFS('💰 Recettes'!$H$10:$H$209,'💰 Recettes'!$J$10:$J$209,3,'💰 Recettes'!$I$10:$I$209,"Oui") | F8: =SUMIFS('💰 Recettes'!$H$10:$H$209,'💰 Recettes'!$J$10:$J$209,4,'💰 Recettes'!$I$10:$I$209,"Oui") | G8: =SUMIFS('💰 Recettes'!$H$10:$H$209,'💰 Recettes'!$J$10:$J$209,5,'💰 Recettes'!$I$10:$I$209,"Oui") | H8: =SUMIFS('💰 Recettes'!$H$10:$H$209,'💰 Recettes'!$J$10:$J$209,6,'💰 Recettes'!$I$10:$I$209,"Oui") | I8: =SUMIFS('💰 Recettes'!$H$10:$H$209,'💰 Recettes'!$J$10:$J$209,7,'💰 Recettes'!$I$10:$I$209,"Oui") | J8: =SUMIFS('💰 Recettes'!$H$10:$H$209,'💰 Recettes'!$J$10:$J$209,8,'💰 Recettes'!$I$10:$I$209,"Oui") | K8: =SUMIFS('💰 Recettes'!$H$10:$H$209,'💰 Recettes'!$J$10:$J$209,9,'💰 Recettes'!$I$10:$I$209,"Oui") | L8: =SUMIFS('💰 Recettes'!$H$10:$H$209,'💰 Recettes'!$J$10:$J$209,10,'💰 Recettes'!$I$10:$I$209,"Oui") | M8: =SUMIFS('💰 Recettes'!$H$10:$H$209,'💰 Recettes'!$J$10:$J$209,11,'💰 Recettes'!$I$10:$I$209,"Oui") | N8: =SUMIFS('💰 Recettes'!$H$10:$H$209,'💰 Recettes'!$J$10:$J$209,12,'💰 Recettes'!$I$10:$I$209,"Oui") | O8: =SUM(C8:N8)
B9: Autres encaissements (apports, subventions…) | C9: 0 | D9: 0 | E9: 0 | F9: 0 | G9: 0 | H9: 0 | I9: 0 | J9: 0 | K9: 0 | L9: 0 | M9: 0 | N9: 0 | O9: =SUM(C9:N9)
B10: Total encaissements | C10: =SUM(C8:C9) | D10: =SUM(D8:D9) | E10: =SUM(E8:E9) | F10: =SUM(F8:F9) | G10: =SUM(G8:G9) | H10: =SUM(H8:H9) | I10: =SUM(I8:I9) | J10: =SUM(J8:J9) | ... N10: =SUM(N8:N9) | O10: =SUM(C10:N10)
B11: DÉCAISSEMENTS
B12: Dépenses payées (TTC) | C12: =SUMIFS('💸 Dépenses'!$I$10:$I$309,'💸 Dépenses'!$K$10:$K$309,1,'💸 Dépenses'!$J$10:$J$309,"Oui") | D12: =SUMIFS('💸 Dépenses'!$I$10:$I$309,'💸 Dépenses'!$K$10:$K$309,2,'💸 Dépenses'!$J$10:$J$309,"Oui") | E12: =SUMIFS('💸 Dépenses'!$I$10:$I$309,'💸 Dépenses'!$K$10:$K$309,3,'💸 Dépenses'!$J$10:$J$309,"Oui") | F12: =SUMIFS('💸 Dépenses'!$I$10:$I$309,'💸 Dépenses'!$K$10:$K$309,4,'💸 Dépenses'!$J$10:$J$309,"Oui") | G12: =SUMIFS('💸 Dépenses'!$I$10:$I$309,'💸 Dépenses'!$K$10:$K$309,5,'💸 Dépenses'!$J$10:$J$309,"Oui") | H12: =SUMIFS('💸 Dépenses'!$I$10:$I$309,'💸 Dépenses'!$K$10:$K$309,6,'💸 Dépenses'!$J$10:$J$309,"Oui") | I12: =SUMIFS('💸 Dépenses'!$I$10:$I$309,'💸 Dépenses'!$K$10:$K$309,7,'💸 Dépenses'!$J$10:$J$309,"Oui") | J12: =SUMIFS('💸 Dépenses'!$I$10:$I$309,'💸 Dépenses'!$K$10:$K$309,8,'💸 Dépenses'!$J$10:$J$309,"Oui") | K12: =SUMIFS('💸 Dépenses'!$I$10:$I$309,'💸 Dépenses'!$K$10:$K$309,9,'💸 Dépenses'!$J$10:$J$309,"Oui") | L12: =SUMIFS('💸 Dépenses'!$I$10:$I$309,'💸 Dépenses'!$K$10:$K$309,10,'💸 Dépenses'!$J$10:$J$309,"Oui") | M12: =SUMIFS('💸 Dépenses'!$I$10:$I$309,'💸 Dépenses'!$K$10:$K$309,11,'💸 Dépenses'!$J$10:$J$309,"Oui") | N12: =SUMIFS('💸 Dépenses'!$I$10:$I$309,'💸 Dépenses'!$K$10:$K$309,12,'💸 Dépenses'!$J$10:$J$309,"Oui") | O12: =SUM(C12:N12)
B13: Salaire net du dirigeant | C13: =SALAIRE_NET | D13: =SALAIRE_NET | E13: =SALAIRE_NET | F13: =SALAIRE_NET | G13: =SALAIRE_NET | H13: =SALAIRE_NET | I13: =SALAIRE_NET | J13: =SALAIRE_NET | ... N13: =SALAIRE_NET | O13: =SUM(C13:N13)
B14: Cotisations sociales URSSAF (estimation) | C14: =ROUND(SALAIRE_NET*TAUX_CHARGES,2) | D14: =ROUND(SALAIRE_NET*TAUX_CHARGES,2) | E14: =ROUND(SALAIRE_NET*TAUX_CHARGES,2) | F14: =ROUND(SALAIRE_NET*TAUX_CHARGES,2) | G14: =ROUND(SALAIRE_NET*TAUX_CHARGES,2) | H14: =ROUND(SALAIRE_NET*TAUX_CHARGES,2) | I14: =ROUND(SALAIRE_NET*TAUX_CHARGES,2) | J14: =ROUND(SALAIRE_NET*TAUX_CHARGES,2) | ... N14: =ROUND(SALAIRE_NET*TAUX_CHARGES,2) | O14: =SUM(C14:N14)
B15: TVA décaissée (estimation) | C15: =MAX(0,'🧾 TVA & Impôts'!$E$7) | D15: =MAX(0,'🧾 TVA & Impôts'!$E$8) | E15: =MAX(0,'🧾 TVA & Impôts'!$E$9) | F15: =MAX(0,'🧾 TVA & Impôts'!$E$10) | G15: =MAX(0,'🧾 TVA & Impôts'!$E$11) | H15: =MAX(0,'🧾 TVA & Impôts'!$E$12) | I15: =MAX(0,'🧾 TVA & Impôts'!$E$13) | J15: =MAX(0,'🧾 TVA & Impôts'!$E$14) | K15: =MAX(0,'🧾 TVA & Impôts'!$E$15) | L15: =MAX(0,'🧾 TVA & Impôts'!$E$16) | M15: =MAX(0,'🧾 TVA & Impôts'!$E$17) | N15: =MAX(0,'🧾 TVA & Impôts'!$E$18) | O15: =SUM(C15:N15)
B16: Acompte d'IS (estimation) | C16: =IF(OR(1=3,1=6,1=9,1=12),'🧾 TVA & Impôts'!$C$31,0) | D16: =IF(OR(2=3,2=6,2=9,2=12),'🧾 TVA & Impôts'!$C$31,0) | E16: =IF(OR(3=3,3=6,3=9,3=12),'🧾 TVA & Impôts'!$C$31,0) | F16: =IF(OR(4=3,4=6,4=9,4=12),'🧾 TVA & Impôts'!$C$31,0) | G16: =IF(OR(5=3,5=6,5=9,5=12),'🧾 TVA & Impôts'!$C$31,0) | H16: =IF(OR(6=3,6=6,6=9,6=12),'🧾 TVA & Impôts'!$C$31,0) | I16: =IF(OR(7=3,7=6,7=9,7=12),'🧾 TVA & Impôts'!$C$31,0) | J16: =IF(OR(8=3,8=6,8=9,8=12),'🧾 TVA & Impôts'!$C$31,0) | K16: =IF(OR(9=3,9=6,9=9,9=12),'🧾 TVA & Impôts'!$C$31,0) | L16: =IF(OR(10=3,10=6,10=9,10=12),'🧾 TVA & Impôts'!$C$31,0) | M16: =IF(OR(11=3,11=6,11=9,11=12),'🧾 TVA & Impôts'!$C$31,0) | N16: =IF(OR(12=3,12=6,12=9,12=12),'🧾 TVA & Impôts'!$C$31,0) | O16: =SUM(C16:N16)
B17: CFE (estimation) | C17: =IF(1=12,CFE_ANNUELLE,0) | D17: =IF(2=12,CFE_ANNUELLE,0) | E17: =IF(3=12,CFE_ANNUELLE,0) | F17: =IF(4=12,CFE_ANNUELLE,0) | G17: =IF(5=12,CFE_ANNUELLE,0) | H17: =IF(6=12,CFE_ANNUELLE,0) | I17: =IF(7=12,CFE_ANNUELLE,0) | J17: =IF(8=12,CFE_ANNUELLE,0) | K17: =IF(9=12,CFE_ANNUELLE,0) | L17: =IF(10=12,CFE_ANNUELLE,0) | M17: =IF(11=12,CFE_ANNUELLE,0) | N17: =IF(12=12,CFE_ANNUELLE,0) | O17: =SUM(C17:N17)
B18: Autres décaissements | C18: 0 | D18: 0 | E18: 0 | F18: 0 | G18: 0 | H18: 0 | I18: 0 | J18: 0 | K18: 0 | L18: 0 | M18: 0 | N18: 0 | O18: =SUM(C18:N18)
B19: Total décaissements | C19: =SUM(C12:C18) | D19: =SUM(D12:D18) | E19: =SUM(E12:E18) | F19: =SUM(F12:F18) | G19: =SUM(G12:G18) | H19: =SUM(H12:H18) | I19: =SUM(I12:I18) | J19: =SUM(J12:J18) | ... N19: =SUM(N12:N18) | O19: =SUM(C19:N19)
B20: SOLDE EN FIN DE MOIS | C20: =C6+C10-C19 | D20: =D6+D10-D19 | E20: =E6+E10-E19 | F20: =F6+F10-F19 | G20: =G6+G10-G19 | H20: =H6+H10-H19 | I20: =I6+I10-I19 | J20: =J6+J10-J19 | ... N20: =N6+N10-N19 | O20: =N20

Sheet 🧾 TVA & Impôts
A1: 🧾 TVA & IMPÔTS
A2: En clair : ce que vous devrez reverser (TVA, URSSAF, IS, CFE) — estimé d'avance pour éviter les surprises.
B3: 💡 Aucune saisie ici (sauf la base IS, modifiable). En franchise en base de TVA, les montants de TVA sont automatiquement à zéro. Montants indicatifs : vérifiez les échéances réelles avec votre comptable.
B5: TVA — SYNTHÈSE MENSUELLE (ESTIMATION) | G5: TVA PAR TRIMESTRE (ESTIMATION)
B6: Mois | C6: TVA collectée | D6: TVA déductible | E6: TVA à décaisser | G6: T1 (janv.–mars) | H6: =SUM($E$7:$E$9)
B7: Janv | C7: =IF(REGIME_TVA="Franchise en base",0,SUMIFS('💰 Recettes'!$G$10:$G$209,'💰 Recettes'!$J$10:$J$209,1)) | D7: =IF(REGIME_TVA="Franchise en base",0,SUMIFS('💸 Dépenses'!$H$10:$H$309,'💸 Dépenses'!$K$10:$K$309,1)) | E7: =C7-D7 | G7: T2 (avr.–juin) | H7: =SUM($E$10:$E$12)
B8: Févr | C8: =IF(REGIME_TVA="Franchise en base",0,SUMIFS('💰 Recettes'!$G$10:$G$209,'💰 Recettes'!$J$10:$J$209,2)) | D8: =IF(REGIME_TVA="Franchise en base",0,SUMIFS('💸 Dépenses'!$H$10:$H$309,'💸 Dépenses'!$K$10:$K$309,2)) | E8: =C8-D8 | G8: T3 (juil.–sept.) | H8: =SUM($E$13:$E$15)
B9: Mars | C9: =IF(REGIME_TVA="Franchise en base",0,SUMIFS('💰 Recettes'!$G$10:$G$209,'💰 Recettes'!$J$10:$J$209,3)) | D9: =IF(REGIME_TVA="Franchise en base",0,SUMIFS('💸 Dépenses'!$H$10:$H$309,'💸 Dépenses'!$K$10:$K$309,3)) | E9: =C9-D9 | G9: T4 (oct.–déc.) | H9: =SUM($E$16:$E$18)
B10: Avr | C10: =IF(REGIME_TVA="Franchise en base",0,SUMIFS('💰 Recettes'!$G$10:$G$209,'💰 Recettes'!$J$10:$J$209,4)) | D10: =IF(REGIME_TVA="Franchise en base",0,SUMIFS('💸 Dépenses'!$H$10:$H$309,'💸 Dépenses'!$K$10:$K$309,4)) | E10: =C10-D10 | G10: Réel simplifié : acomptes en juillet et décembre, régularisation en mai.
B11: Mai | C11: =IF(REGIME_TVA="Franchise en base",0,SUMIFS('💰 Recettes'!$G$10:$G$209,'💰 Recettes'!$J$10:$J$209,5)) | D11: =IF(REGIME_TVA="Franchise en base",0,SUMIFS('💸 Dépenses'!$H$10:$H$309,'💸 Dépenses'!$K$10:$K$309,5)) | E11: =C11-D11
B12: Juin | C12: =IF(REGIME_TVA="Franchise en base",0,SUMIFS('💰 Recettes'!$G$10:$G$209,'💰 Recettes'!$J$10:$J$209,6)) | D12: =IF(REGIME_TVA="Franchise en base",0,SUMIFS('💸 Dépenses'!$H$10:$H$309,'💸 Dépenses'!$K$10:$K$309,6)) | E12: =C12-D12 | G12: 💡 À PROVISIONNER CE MOIS-CI (ESTIMATION)
B13: Juil | C13: =IF(REGIME_TVA="Franchise en base",0,SUMIFS('💰 Recettes'!$G$10:$G$209,'💰 Recettes'!$J$10:$J$209,7)) | D13: =IF(REGIME_TVA="Franchise en base",0,SUMIFS('💸 Dépenses'!$H$10:$H$309,'💸 Dépenses'!$K$10:$K$309,7)) | E13: =C13-D13 | G13: TVA du mois (estimation) | H13: =MAX(0,INDEX($E$7:$E$18,IF(YEAR(TODAY())>ANNEE,12,IF(YEAR(TODAY())<ANNEE,1,MONTH(TODAY())))))
B14: Août | C14: =IF(REGIME_TVA="Franchise en base",0,SUMIFS('💰 Recettes'!$G$10:$G$209,'💰 Recettes'!$J$10:$J$209,8)) | D14: =IF(REGIME_TVA="Franchise en base",0,SUMIFS('💸 Dépenses'!$H$10:$H$309,'💸 Dépenses'!$K$10:$K$309,8)) | E14: =C14-D14 | G14: Cotisations URSSAF (estimation) | H14: =ROUND(SALAIRE_NET*TAUX_CHARGES,2)
B15: Sept | C15: =IF(REGIME_TVA="Franchise en base",0,SUMIFS('💰 Recettes'!$G$10:$G$209,'💰 Recettes'!$J$10:$J$209,9)) | D15: =IF(REGIME_TVA="Franchise en base",0,SUMIFS('💸 Dépenses'!$H$10:$H$309,'💸 Dépenses'!$K$10:$K$309,9)) | E15: =C15-D15 | G15: Acompte d'IS (estimation) | H15: =IF(OR(IF(YEAR(TODAY())>ANNEE,12,IF(YEAR(TODAY())<ANNEE,1,MONTH(TODAY())))=3,IF(YEAR(TODAY())>ANNEE,12,IF(YEAR(TODAY())<ANNEE,1,MONTH(TODAY())))=6,IF(YEAR(TODAY())>ANNEE,12,IF(YEAR(TODAY())<ANNEE,1,MONTH(TODAY())))=9,IF(YEAR(TODAY())>ANNEE,12,IF(YEAR(TODAY())<ANNEE,1,MONTH(TODAY())))=12),$C$31,0)
B16: Oct | C16: =IF(REGIME_TVA="Franchise en base",0,SUMIFS('💰 Recettes'!$G$10:$G$209,'💰 Recettes'!$J$10:$J$209,10)) | D16: =IF(REGIME_TVA="Franchise en base",0,SUMIFS('💸 Dépenses'!$H$10:$H$309,'💸 Dépenses'!$K$10:$K$309,10)) | E16: =C16-D16 | G16: CFE — 15 décembre (estimation) | H16: =IF(IF(YEAR(TODAY())>ANNEE,12,IF(YEAR(TODAY())<ANNEE,1,MONTH(TODAY())))=12,CFE_ANNUELLE,0)
B17: Nov | C17: =IF(REGIME_TVA="Franchise en base",0,SUMIFS('💰 Recettes'!$G$10:$G$209,'💰 Recettes'!$J$10:$J$209,11)) | D17: =IF(REGIME_TVA="Franchise en base",0,SUMIFS('💸 Dépenses'!$H$10:$H$309,'💸 Dépenses'!$K$10:$K$309,11)) | E17: =C17-D17 | G17: TOTAL À PROVISIONNER | H17: =SUM(H13:H16)
B18: Déc | C18: =IF(REGIME_TVA="Franchise en base",0,SUMIFS('💰 Recettes'!$G$10:$G$209,'💰 Recettes'!$J$10:$J$209,12)) | D18: =IF(REGIME_TVA="Franchise en base",0,SUMIFS('💸 Dépenses'!$H$10:$H$309,'💸 Dépenses'!$K$10:$K$309,12)) | E18: =C18-D18
B19: Total annuel | C19: =SUM(C7:C18) | D19: =SUM(D7:D18) | E19: =SUM(E7:E18)
B21: COTISATIONS SOCIALES DU DIRIGEANT — URSSAF (ESTIMATION) | G21: CFE (ESTIMATION)
B22: Statut | C22: =STATUT | G22: Montant estimé (⚙️ Paramètres) | H22: =CFE_ANNUELLE
B23: Taux de charges (sur le net) | C23: =TAUX_CHARGES | G23: Échéance | H23: 15 décembre
B24: Salaire net mensuel | C24: =SALAIRE_NET
B25: Cotisations mensuelles (estimation) | C25: =ROUND(SALAIRE_NET*TAUX_CHARGES,2)
B26: Cotisations annuelles (estimation) | C26: =$C$25*12
B27: Taux moyens indicatifs (modifiables dans ⚙️ Paramètres), à ajuster selon votre situation.
B28: IMPÔT SUR LES SOCIÉTÉS (ESTIMATION)
B29: Base : résultat prévisionnel annuel (modifiable) | C29: ='📋 Budget'!$O$33
B30: IS estimé (barème 15 % / 25 %) | C30: =IF($C$29<=0,0,IF($C$29<=SEUIL_IS,ROUND($C$29*TAUX_IS_REDUIT,2),ROUND(SEUIL_IS*TAUX_IS_REDUIT+($C$29-SEUIL_IS)*TAUX_IS_NORMAL,2)))
B31: Acompte trimestriel (IS ÷ 4) | C31: =ROUND($C$30/4,2)
B32: Échéances des acomptes : 15 mars · 15 juin · 15 septembre · 15 décembre.

Sheet 📅 Échéancier
A1: 📅 ÉCHÉANCIER FISCAL & SOCIAL
A2: En clair : toutes vos dates limites (TVA, URSSAF, IS, CFE) au même endroit — fini les mauvaises surprises.
B3: 💡 Les lignes s'adaptent automatiquement à votre régime de TVA (⚙️ Paramètres). Passez une échéance en « Payé » quand c'est réglé : le compte à rebours et les totaux se mettent à jour seuls.
I4: Zone de calcul — ne pas supprimer
B5: PROCHAINE ÉCHÉANCE | D5: À PRÉVOIR CE MOIS-CI | F5: RESTE À PAYER SUR L'ANNÉE | I5: Prochaine échéance (date) | J5: =IF(COUNT($H$11:$H$43)=0,0,MIN($H$11:$H$43))
B6: =IF($J$5=0,"—",$J$5) | D6: =$J$9 | F6: =$J$10 | I6: Prochaine échéance (nature) | J6: =IF($J$5=0,"—",INDEX($D$11:$D$43,MATCH($J$5,$B$11:$B$43,0)))
B7: =IF($J$5=0,"aucune échéance à venir",$J$6&" · dans "&$J$8&" j") | D7: échéances non payées du mois (estimation) | F7: toutes échéances à venir (estimation) | I7: Prochaine échéance (montant) | J7: =IF($J$5=0,0,INDEX($E$11:$E$43,MATCH($J$5,$B$11:$B$43,0)))
I8: Prochaine échéance (jours) | J8: =IF($J$5=0,0,$J$5-TODAY())
I9: À prévoir ce mois-ci | J9: =SUMIFS($E$11:$E$43,$B$11:$B$43,">="&DATE(ANNEE,IF(YEAR(TODAY())>ANNEE,12,IF(YEAR(TODAY())<ANNEE,1,MONTH(TODAY()))),1),$B$11:$B$43,"<"&DATE(ANNEE,IF(YEAR(TODAY())>ANNEE,12,IF(YEAR(TODAY())<ANNEE,1,MONTH(TODAY())))+1,1),$F$11:$F$43,"<>Payé")
B10: Date | C10: Organisme | D10: Nature | E10: Montant estimé | F10: Statut | G10: Compte à rebours | I10: Reste à payer sur l'année | J10: =SUMIFS($E$11:$E$43,$B$11:$B$43,">="&TODAY(),$F$11:$F$43,"<>Payé")
B11: =DATE(ANNEE,1,JOUR_URSSAF*1) | C11: URSSAF | D11: Cotisations sociales — janvier (estimation) | E11: =ROUND(SALAIRE_NET*TAUX_CHARGES,2) | F11: À venir | G11: =IF($B11="","",IF($F11="Payé","✓ Payé",IF($B11<TODAY(),"Passée",IF($B11-TODAY()<7,"⚠️ URGENT — dans "&($B11-TODAY())&" j","dans "&($B11-TODAY())&" j")))) | H11: =IF(AND($B11<>"",$F11<>"Payé",$B11>=TODAY()),$B11,"")
B12: =IF(REGIME_TVA="Réel normal",DATE(ANNEE,2,15),"") | C12: Impôts (TVA) | D12: TVA de janvier (estimation) | E12: =IF(REGIME_TVA="Réel normal",MAX(0,'🧾 TVA & Impôts'!$E$7),"") | F12: À venir | G12: =IF($B12="","",IF($F12="Payé","✓ Payé",IF($B12<TODAY(),"Passée",IF($B12-TODAY()<7,"⚠️ URGENT — dans "&($B12-TODAY())&" j","dans "&($B12-TODAY())&" j")))) | H12: =IF(AND($B12<>"",$F12<>"Payé",$B12>=TODAY()),$B12,"")
B13: =DATE(ANNEE,2,JOUR_URSSAF*1) | C13: URSSAF | D13: Cotisations sociales — février (estimation) | E13: =ROUND(SALAIRE_NET*TAUX_CHARGES,2) | F13: À venir | G13: =IF($B13="","",IF($F13="Payé","✓ Payé",IF($B13<TODAY(),"Passée",IF($B13-TODAY()<7,"⚠️ URGENT — dans "&($B13-TODAY())&" j","dans "&($B13-TODAY())&" j")))) | H13: =IF(AND($B13<>"",$F13<>"Payé",$B13>=TODAY()),$B13,"")
B14: =IF(REGIME_TVA="Réel normal",DATE(ANNEE,3,15),"") | C14: Impôts (TVA) | D14: TVA de février (estimation) | E14: =IF(REGIME_TVA="Réel normal",MAX(0,'🧾 TVA & Impôts'!$E$8),"") | F14: À venir | G14: =IF($B14="","",IF($F14="Payé","✓ Payé",IF($B14<TODAY(),"Passée",IF($B14-TODAY()<7,"⚠️ URGENT — dans "&($B14-TODAY())&" j","dans "&($B14-TODAY())&" j")))) | H14: =IF(AND($B14<>"",$F14<>"Payé",$B14>=TODAY()),$B14,"")
B15: =DATE(ANNEE,3,JOUR_URSSAF*1) | C15: URSSAF | D15: Cotisations sociales — mars (estimation) | E15: =ROUND(SALAIRE_NET*TAUX_CHARGES,2) | F15: À venir | G15: =IF($B15="","",IF($F15="Payé","✓ Payé",IF($B15<TODAY(),"Passée",IF($B15-TODAY()<7,"⚠️ URGENT — dans "&($B15-TODAY())&" j","dans "&($B15-TODAY())&" j")))) | H15: =IF(AND($B15<>"",$F15<>"Payé",$B15>=TODAY()),$B15,"")
B16: =IF(REGIME_TVA="Réel normal",DATE(ANNEE,4,15),"") | C16: Impôts (TVA) | D16: TVA de mars (estimation) | E16: =IF(REGIME_TVA="Réel normal",MAX(0,'🧾 TVA & Impôts'!$E$9),"") | F16: À venir | G16: =IF($B16="","",IF($F16="Payé","✓ Payé",IF($B16<TODAY(),"Passée",IF($B16-TODAY()<7,"⚠️ URGENT — dans "&($B16-TODAY())&" j","dans "&($B16-TODAY())&" j")))) | H16: =IF(AND($B16<>"",$F16<>"Payé",$B16>=TODAY()),$B16,"")
B17: =DATE(ANNEE,4,JOUR_URSSAF*1) | C17: URSSAF | D17: Cotisations sociales — avril (estimation) | E17: =ROUND(SALAIRE_NET*TAUX_CHARGES,2) | F17: À venir | G17: =IF($B17="","",IF($F17="Payé","✓ Payé",IF($B17<TODAY(),"Passée",IF($B17-TODAY()<7,"⚠️ URGENT — dans "&($B17-TODAY())&" j","dans "&($B17-TODAY())&" j")))) | H17: =IF(AND($B17<>"",$F17<>"Payé",$B17>=TODAY()),$B17,"")
B18: =IF(REGIME_TVA="Réel normal",DATE(ANNEE,5,15),"") | C18: Impôts (TVA) | D18: TVA de avril (estimation) | E18: =IF(REGIME_TVA="Réel normal",MAX(0,'🧾 TVA & Impôts'!$E$10),"") | F18: À venir | G18: =IF($B18="","",IF($F18="Payé","✓ Payé",IF($B18<TODAY(),"Passée",IF($B18-TODAY()<7,"⚠️ URGENT — dans "&($B18-TODAY())&" j","dans "&($B18-TODAY())&" j")))) | H18: =IF(AND($B18<>"",$F18<>"Payé",$B18>=TODAY()),$B18,"")
B19: =DATE(ANNEE,5,JOUR_URSSAF*1) | C19: URSSAF | D19: Cotisations sociales — mai (estimation) | E19: =ROUND(SALAIRE_NET*TAUX_CHARGES,2) | F19: À venir | G19: =IF($B19="","",IF($F19="Payé","✓ Payé",IF($B19<TODAY(),"Passée",IF($B19-TODAY()<7,"⚠️ URGENT — dans "&($B19-TODAY())&" j","dans "&($B19-TODAY())&" j")))) | H19: =IF(AND($B19<>"",$F19<>"Payé",$B19>=TODAY()),$B19,"")
B20: =IF(REGIME_TVA="Réel normal",DATE(ANNEE,6,15),"") | C20: Impôts (TVA) | D20: TVA de mai (estimation) | E20: =IF(REGIME_TVA="Réel normal",MAX(0,'🧾 TVA & Impôts'!$E$11),"") | F20: À venir | G20: =IF($B20="","",IF($F20="Payé","✓ Payé",IF($B20<TODAY(),"Passée",IF($B20-TODAY()<7,"⚠️ URGENT — dans "&($B20-TODAY())&" j","dans "&($B20-TODAY())&" j")))) | H20: =IF(AND($B20<>"",$F20<>"Payé",$B20>=TODAY()),$B20,"")
B21: =DATE(ANNEE,6,JOUR_URSSAF*1) | C21: URSSAF | D21: Cotisations sociales — juin (estimation) | E21: =ROUND(SALAIRE_NET*TAUX_CHARGES,2) | F21: À venir | G21: =IF($B21="","",IF($F21="Payé","✓ Payé",IF($B21<TODAY(),"Passée",IF($B21-TODAY()<7,"⚠️ URGENT — dans "&($B21-TODAY())&" j","dans "&($B21-TODAY())&" j")))) | H21: =IF(AND($B21<>"",$F21<>"Payé",$B21>=TODAY()),$B21,"")
B22: =IF(REGIME_TVA="Réel normal",DATE(ANNEE,7,15),"") | C22: Impôts (TVA) | D22: TVA de juin (estimation) | E22: =IF(REGIME_TVA="Réel normal",MAX(0,'🧾 TVA & Impôts'!$E$12),"") | F22: À venir | G22: =IF($B22="","",IF($F22="Payé","✓ Payé",IF($B22<TODAY(),"Passée",IF($B22-TODAY()<7,"⚠️ URGENT — dans "&($B22-TODAY())&" j","dans "&($B22-TODAY())&" j")))) | H22: =IF(AND($B22<>"",$F22<>"Payé",$B22>=TODAY()),$B22,"")
B23: =DATE(ANNEE,7,JOUR_URSSAF*1) | C23: URSSAF | D23: Cotisations sociales — juillet (estimation) | E23: =ROUND(SALAIRE_NET*TAUX_CHARGES,2) | F23: À venir | G23: =IF($B23="","",IF($F23="Payé","✓ Payé",IF($B23<TODAY(),"Passée",IF($B23-TODAY()<7,"⚠️ URGENT — dans "&($B23-TODAY())&" j","dans "&($B23-TODAY())&" j")))) | H23: =IF(AND($B23<>"",$F23<>"Payé",$B23>=TODAY()),$B23,"")
B24: =IF(REGIME_TVA="Réel normal",DATE(ANNEE,8,15),"") | C24: Impôts (TVA) | D24: TVA de juillet (estimation) | E24: =IF(REGIME_TVA="Réel normal",MAX(0,'🧾 TVA & Impôts'!$E$13),"") | F24: À venir | G24: =IF($B24="","",IF($F24="Payé","✓ Payé",IF($B24<TODAY(),"Passée",IF($B24-TODAY()<7,"⚠️ URGENT — dans "&($B24-TODAY())&" j","dans "&($B24-TODAY())&" j")))) | H24: =IF(AND($B24<>"",$F24<>"Payé",$B24>=TODAY()),$B24,"")
B25: =DATE(ANNEE,8,JOUR_URSSAF*1) | C25: URSSAF | D25: Cotisations sociales — août (estimation) | E25: =ROUND(SALAIRE_NET*TAUX_CHARGES,2) | F25: À venir | G25: =IF($B25="","",IF($F25="Payé","✓ Payé",IF($B25<TODAY(),"Passée",IF($B25-TODAY()<7,"⚠️ URGENT — dans "&($B25-TODAY())&" j","dans "&($B25-TODAY())&" j")))) | H25: =IF(AND($B25<>"",$F25<>"Payé",$B25>=TODAY()),$B25,"")
B26: =IF(REGIME_TVA="Réel normal",DATE(ANNEE,9,15),"") | C26: Impôts (TVA) | D26: TVA de août (estimation) | E26: =IF(REGIME_TVA="Réel normal",MAX(0,'🧾 TVA & Impôts'!$E$14),"") | F26: À venir | G26: =IF($B26="","",IF($F26="Payé","✓ Payé",IF($B26<TODAY(),"Passée",IF($B26-TODAY()<7,"⚠️ URGENT — dans "&($B26-TODAY())&" j","dans "&($B26-TODAY())&" j")))) | H26: =IF(AND($B26<>"",$F26<>"Payé",$B26>=TODAY()),$B26,"")
B27: =DATE(ANNEE,9,JOUR_URSSAF*1) | C27: URSSAF | D27: Cotisations sociales — septembre (estimation) | E27: =ROUND(SALAIRE_NET*TAUX_CHARGES,2) | F27: À venir | G27: =IF($B27="","",IF($F27="Payé","✓ Payé",IF($B27<TODAY(),"Passée",IF($B27-TODAY()<7,"⚠️ URGENT — dans "&($B27-TODAY())&" j","dans "&($B27-TODAY())&" j")))) | H27: =IF(AND($B27<>"",$F27<>"Payé",$B27>=TODAY()),$B27,"")
B28: =IF(REGIME_TVA="Réel normal",DATE(ANNEE,10,15),"") | C28: Impôts (TVA) | D28: TVA de septembre (estimation) | E28: =IF(REGIME_TVA="Réel normal",MAX(0,'🧾 TVA & Impôts'!$E$15),"") | F28: À venir | G28: =IF($B28="","",IF($F28="Payé","✓ Payé",IF($B28<TODAY(),"Passée",IF($B28-TODAY()<7,"⚠️ URGENT — dans "&($B28-TODAY())&" j","dans "&($B28-TODAY())&" j")))) | H28: =IF(AND($B28<>"",$F28<>"Payé",$B28>=TODAY()),$B28,"")
B29: =DATE(ANNEE,10,JOUR_URSSAF*1) | C29: URSSAF | D29: Cotisations sociales — octobre (estimation) | E29: =ROUND(SALAIRE_NET*TAUX_CHARGES,2) | F29: À venir | G29: =IF($B29="","",IF($F29="Payé","✓ Payé",IF($B29<TODAY(),"Passée",IF($B29-TODAY()<7,"⚠️ URGENT — dans "&($B29-TODAY())&" j","dans "&($B29-TODAY())&" j")))) | H29: =IF(AND($B29<>"",$F29<>"Payé",$B29>=TODAY()),$B29,"")
B30: =IF(REGIME_TVA="Réel normal",DATE(ANNEE,11,15),"") | C30: Impôts (TVA) | D30: TVA de octobre (estimation) | E30: =IF(REGIME_TVA="Réel normal",MAX(0,'🧾 TVA & Impôts'!$E$16),"") | F30: À venir | G30: =IF($B30="","",IF($F30="Payé","✓ Payé",IF($B30<TODAY(),"Passée",IF($B30-TODAY()<7,"⚠️ URGENT — dans "&($B30-TODAY())&" j","dans "&($B30-TODAY())&" j")))) | H30: =IF(AND($B30<>"",$F30<>"Payé",$B30>=TODAY()),$B30,"")
B31: =DATE(ANNEE,11,JOUR_URSSAF*1) | C31: URSSAF | D31: Cotisations sociales — novembre (estimation) | E31: =ROUND(SALAIRE_NET*TAUX_CHARGES,2) | F31: À venir | G31: =IF($B31="","",IF($F31="Payé","✓ Payé",IF($B31<TODAY(),"Passée",IF($B31-TODAY()<7,"⚠️ URGENT — dans "&($B31-TODAY())&" j","dans "&($B31-TODAY())&" j")))) | H31: =IF(AND($B31<>"",$F31<>"Payé",$B31>=TODAY()),$B31,"")
